<?xml version="1.0"?>
<robot name="racecar">
    <material name="black">
        <color rgba="0.2 0.2 0.2 1." />
    </material>
    <material name="blue">
        <color rgba="0.3 0.57 1. 1." />
    </material>
    <link name="base_link">
        <visual>
            <origin xyz="0.1651 0 0.09" />
            <geometry>
                <box size="0.3302 0.2032 0.1" />
            </geometry>
            <material name="blue" />
        </visual>
    </link>
    <joint name="base_to_laser_model" type="fixed">
        <parent link="base_link" />
        <child link="laser_model" />
        <origin xyz="0.275 0 0.165" />
    </joint>
    <link name="laser_model">
        <visual>
            <geometry>
                <cylinder length="0.05" radius="0.026" />
            </geometry>
            <material name="black" />
        </visual>
    </link>
    <joint name="base_to_back_left_wheel" type="fixed">
        <parent link="base_link" />
        <child link="back_left_wheel" />
        <origin xyz="0 0.12065 0.0508" />
    </joint>
    <link name="back_left_wheel">
        <visual>
            <geometry>
                <cylinder length="0.0381" radius="0.0508" />
            </geometry>
            <material name="black" />
            <origin rpy="1.5707963267948966 0 0" />
        </visual>
    </link>
    <joint name="base_to_back_right_wheel" type="fixed">
        <parent link="base_link" />
        <child link="back_right_wheel" />
        <origin xyz="0 -0.12065 0.0508" />
    </joint>
    <link name="back_right_wheel">
        <visual>
            <geometry>
                <cylinder length="0.0381" radius="0.0508" />
            </geometry>
            <material name="black" />
            <origin rpy="1.5707963267948966 0 0" />
        </visual>
    </link>
    <joint name="base_to_front_left_hinge" type="fixed">
        <parent link="base_link" />
        <child link="front_left_hinge" />
        <origin xyz="0.3302 0.12065 0.0508" />
    </joint>
    <link name="front_left_hinge" />
    <joint name="front_left_hinge_to_wheel" type="continuous">
        <parent link="front_left_hinge" />
        <child link="front_left_wheel" />
    </joint>
    <link name="front_left_wheel">
        <visual>
            <geometry>
                <cylinder length="0.0381" radius="0.0508" />
            </geometry>
            <material name="black" />
            <origin rpy="1.5707963267948966 0 0" />
        </visual>
    </link>
    <joint name="base_to_front_right_hinge" type="fixed">
        <parent link="base_link" />
        <child link="front_right_hinge" />
        <origin xyz="0.3302 -0.12065 0.0508" />
    </joint>
    <link name="front_right_hinge" />
    <joint name="front_right_hinge_to_wheel" type="continuous">
        <parent link="front_right_hinge" />
        <child link="front_right_wheel" />
    </joint>
    <link name="front_right_wheel">
        <visual>
            <geometry>
                <cylinder length="0.0381" radius="0.0508" />
            </geometry>
            <material name="black" />
            <origin rpy="1.5707963267948966 0 0" />
        </visual>
    </link>
</robot>